Workbook

Sheet LCC-Pico-Stepper_v2_4
A1: Qty | B1: Reference | C1: Value | D1: Source | E1: code | F1: Part | G1: Datasheet | H1: Footprint | I1: DNP | J1: populated | K1: part cost | L1: build | M1: notes
A2: 2 | B2: C1,C3 | C2: 0.1uF | D2: mouser | E2: =LEFT(B2,1) -> C | F2: C1206C104K3RAC7411 | G2: ~ | H2: Capacitor_SMD:C_1206_3216Metric_Pad1.33x1.80mm_HandSolder | J2: x | K2: =VLOOKUP(F2,Stock!C:G,4,FALSE) -> 0.058 | L2: =IF(ISBLANK(J2),0,A2*K2) -> 0.116
A3: 3 | B3: C6,C15,C19 | C3: 100nF | D3: mouser | E3: =LEFT(B3,1) -> C | F3: C1206C104K3RAC7411 | G3: ~ | H3: Capacitor_SMD:C_1206_3216Metric_Pad1.33x1.80mm_HandSolder | J3: x | K3: =VLOOKUP(F3,Stock!C:G,4,FALSE) -> 0.058 | L3: =IF(ISBLANK(J3),0,A3*K3) -> 0.174
A4: 1 | B4: C7 | C4: 1uF | D4: mouser | E4: =LEFT(B4,1) -> C | F4: CL31B105KAHNFNE | G4: ~ | H4: Capacitor_SMD:C_1206_3216Metric_Pad1.33x1.80mm_HandSolder | J4: x | K4: =VLOOKUP(F4,Stock!C:G,4,FALSE) -> 0.031 | L4: =IF(ISBLANK(J4),0,A4*K4) -> 0.031
A5: 2 | B5: C13,C14 | C5: 22pF | D5: mouser | E5: =LEFT(B5,1) -> C | F5: C1206C220J3HACTU | G5: ~ | H5: Capacitor_SMD:C_1206_3216Metric_Pad1.33x1.80mm_HandSolder | J5: x | K5: =VLOOKUP(F5,Stock!C:G,4,FALSE) -> 0.057 | L5: =IF(ISBLANK(J5),0,A5*K5) -> 0.114
A6: 7 | B6: C4,C5,C8,C9,C10,C11,C12 | C6: 22uF | D6: mouser | E6: =LEFT(B6,1) -> C | F6: CL31A226MOCLNNC | G6: ~ | H6: Capacitor_SMD:C_1206_3216Metric_Pad1.33x1.80mm_HandSolder | J6: x | K6: =VLOOKUP(F6,Stock!C:G,4,FALSE) -> 0.066 | L6: =IF(ISBLANK(J6),0,A6*K6) -> 0.462
A7: 1 | B7: C16 | C7: 4.7uF | D7: mouser | E7: =LEFT(B7,1) -> C | F7: CL31B475KOHNFNE | G7: ~ | H7: Capacitor_SMD:C_1206_3216Metric_Pad1.33x1.80mm_HandSolder | J7: x | K7: =VLOOKUP(F7,Stock!C:G,4,FALSE) -> 0.048 | L7: =IF(ISBLANK(J7),0,A7*K7) -> 0.048
A8: 1 | B8: C2 | C8: 470uF | D8: mouser | E8: =LEFT(B8,1) -> C | F8: EEU-FR1V471L | G8: ~ | H8: Capacitor_THT:CP_Radial_D8.0mm_P3.50mm | J8: x | K8: =VLOOKUP(F8,Stock!C:G,4,FALSE) -> 0.3 | L8: =IF(ISBLANK(J8),0,A8*K8) -> 0.3
A9: 4 | B9: D4,D5,D7,D8 | C9: LED | D9: mouser | E9: =LEFT(B9,1) -> D | F9: LTST-C230GKT | G9: ~ | H9: LED_SMD:LED_1206_3216Metric_Pad1.42x1.75mm_HandSolder | J9: x | K9: =VLOOKUP(F9,Stock!C:G,4,FALSE) -> 0.061 | L9: =IF(ISBLANK(J9),0,A9*K9) -> 0.244
A10: 4 | B10: D2,D3,D9,D10 | C10: M7 | D10: mouser | E10: =LEFT(B10,1) -> D | F10: M7 | G10: ~ | H10: SamacSys_Parts:DIOM5327X240N | J10: x | K10: =VLOOKUP(F10,Stock!C:G,4,FALSE) -> 0.025 | L10: =IF(ISBLANK(J10),0,A10*K10) -> 0.1
A11: 2 | B11: D6,D11 | C11: PwrG | D11: mouser | E11: =LEFT(B11,1) -> D | F11: LTST-C230GKT | G11: ~ | H11: LED_SMD:LED_1206_3216Metric_Pad1.42x1.75mm_HandSolder | J11: x | K11: =VLOOKUP(F11,Stock!C:G,4,FALSE) -> 0.061 | L11: =IF(ISBLANK(J11),0,A11*K11) -> 0.122
A12: 2 | B12: F1,F2 | C12: 0ZCG0035AF2C | D12: mouser | E12: =LEFT(B12,1) -> F | F12: 0ZCG0035AF2C | G12: https://www.mouser.com/datasheet/2/643/0ZCG_Nov2016-1132141.pdf | H12: SamacSys_Parts:FUSC4632X70N | J12: x | K12: =VLOOKUP(F12,Stock!C:G,4,FALSE) -> 0.121 | L12: =IF(ISBLANK(J12),0,A12*K12) -> 0.242
A13: 1 | B13: IC5 | C13: MB85RCxxxV | D13: mouser | E13: =LEFT(B13,1) -> I | F13: BR24G512F-3AGTE2 | G13: FRAM or EEPROM chip | H13: SamacSys_Parts:SOIC127P600X175-8N | K13: =VLOOKUP(F13,Stock!C:G,4,FALSE) -> 0.744 | L13: =IF(ISBLANK(J13),0,A13*K13) -> 0
A14: 1 | B14: IC2 | C14: MCP2518FDT-E_SL | D14: mouser | E14: =LEFT(B14,1) -> I | F14: MCP2518FDT-E/SL | G14: https://datasheet.datasheetarchive.com/originals/distributors/Datasheets_SAMA/744760637e861ab0ee43f380fa65a694.pdf | H14: SamacSys_Parts:SOIC127P600X175-14N | J14: x | K14: =VLOOKUP(F14,Stock!C:G,4,FALSE) -> 1.96 | L14: =IF(ISBLANK(J14),0,A14*K14) -> 1.96
A15: 1 | B15: IC3 | C15: TJA1042T_3_1J | D15: mouser | E15: =LEFT(B15,1) -> I | F15: TJA1042T/3/1J | G15: http://www.nxp.com/docs/en/data-sheet/TJA1042.pdf | H15: SamacSys_Parts:SOIC127P600X175-8N | J15: x | K15: =VLOOKUP(F15,Stock!C:G,4,FALSE) -> 1.23 | L15: =IF(ISBLANK(J15),0,A15*K15) -> 1.23 | M15: used MCP2562
A16: 1 | B16: IC1 | C16: TPS54294PWPR | D16: mouser | E16: =LEFT(B16,1) -> I | F16: TPS54294PWPR | G16: http://www.ti.com/lit/gpn/tps54294 | H16: SamacSys_Parts:SOP65P640X120-17N | J16: x | K16: =VLOOKUP(F16,Stock!C:G,4,FALSE) -> 1.66 | L16: =IF(ISBLANK(J16),0,A16*K16) -> 1.66
A17: 2 | B17: J1,J2 | C17: RJ45 | D17: mouser | E17: =LEFT(B17,1) -> J | F17: MTJ-880X1 | G17: https://app.adam-tech.com/products/download/data_sheet/203795/mtj-880x1-data-sheet.pdf | H17: SamacSys_Parts:MTJ880X1 | J17: x | K17: =VLOOKUP(F17,Stock!C:G,4,FALSE) -> 0.499 | L17: =IF(ISBLANK(J17),0,A17*K17) -> 0.998
A18: 1 | B18: L1 | C18: SRP3212A-2R2M | D18: mouser | E18: =LEFT(B18,1) -> L | F18: SRP3212A-2R2M | G18: https://www.bourns.com/docs/product-datasheets/srp3212.pdf | H18: SamacSys_Parts:INDC3225X120N | J18: x | K18: =VLOOKUP(F18,Stock!C:G,4,FALSE) -> 0.171 | L18: =IF(ISBLANK(J18),0,A18*K18) -> 0.171
A19: 1 | B19: L2 | C19: SRP3212A-3R3M | D19: mouser | E19: =LEFT(B19,1) -> L | F19: SRP3212A-3R3M | G19: https://www.bourns.com/docs/product-datasheets/srp3212.pdf | H19: SamacSys_Parts:INDC3225X120N | J19: x | K19: =VLOOKUP(F19,Stock!C:G,4,FALSE) -> 0.172 | L19: =IF(ISBLANK(J19),0,A19*K19) -> 0.172
A20: 1 | B20: Q1 | C20: DMG2305UX-7 | D20: mouser | E20: =LEFT(B20,1) -> Q | F20: DMG2305UX-7 | G20: https://www.diodes.com//assets/Datasheets/DMG2305UX.pdf | H20: SamacSys_Parts:SOT96P240X115-3N | J20: x | K20: =VLOOKUP(F20,Stock!C:G,4,FALSE) -> 0.101 | L20: =IF(ISBLANK(J20),0,A20*K20) -> 0.101
A21: 5 | B21: R8,R9,R13,R14,R16 | C21: 10K | D21: mouser | E21: =LEFT(B21,1) -> R | F21: RT1206FRD0710KL | H21: Resistor_SMD:R_1206_3216Metric_Pad1.30x1.75mm_HandSolder | J21: x | K21: =VLOOKUP(F21,Stock!C:G,4,FALSE) -> 0.035 | L21: =IF(ISBLANK(J21),0,A21*K21) -> 0.175
A22: 1 | B22: R1 | C22: 124K | D22: mouser | E22: =LEFT(B22,1) -> R | F22: ERA-8AEB1243V | H22: Resistor_SMD:R_1206_3216Metric_Pad1.30x1.75mm_HandSolder | J22: x | K22: =VLOOKUP(F22,Stock!C:G,4,FALSE) -> 0.278 | L22: =IF(ISBLANK(J22),0,A22*K22) -> 0.278
A23: 2 | B23: R2,R4 | C23: 22.1K | D23: mouser | E23: =LEFT(B23,1) -> R | F23: ERA-8AEB2212V | H23: Resistor_SMD:R_1206_3216Metric_Pad1.30x1.75mm_HandSolder | J23: x | K23: =VLOOKUP(F23,Stock!C:G,4,FALSE) -> 0.278 | L23: =IF(ISBLANK(J23),0,A23*K23) -> 0.556
A24: 1 | B24: R11 | C24: 2K | D24: mouser | E24: =LEFT(B24,1) -> R | F24: RT1206FRE072KL | H24: Resistor_SMD:R_1206_3216Metric_Pad1.30x1.75mm_HandSolder | J24: x | K24: =VLOOKUP(F24,Stock!C:G,4,FALSE) -> 0.039 | L24: =IF(ISBLANK(J24),0,A24*K24) -> 0.039
A25: 3 | B25: R5,R10,R12 | C25: 3K | D25: mouser | E25: =LEFT(B25,1) -> R | F25: RT1206FRE073KL | H25: Resistor_SMD:R_1206_3216Metric_Pad1.30x1.75mm_HandSolder | J25: x | K25: =VLOOKUP(F25,Stock!C:G,4,FALSE) -> 0.034 | L25: =IF(ISBLANK(J25),0,A25*K25) -> 0.102
A26: 1 | B26: R7 | C26: 560R | D26: mouser | E26: =LEFT(B26,1) -> R | F26: RT1206FRE07560RL | H26: Resistor_SMD:R_1206_3216Metric_Pad1.30x1.75mm_HandSolder | J26: x | K26: =VLOOKUP(F26,Stock!C:G,4,FALSE) -> 0.034 | L26: =IF(ISBLANK(J26),0,A26*K26) -> 0.034
A27: 1 | B27: R15 | C27: 6k8 | D27: mouser | E27: =LEFT(B27,1) -> R | F27: RT1206DRD076K8L | H27: Resistor_SMD:R_1206_3216Metric_Pad1.30x1.75mm_HandSolder | J27: x | K27: =VLOOKUP(F27,Stock!C:G,4,FALSE) -> 0.071 | L27: =IF(ISBLANK(J27),0,A27*K27) -> 0.071
A28: 1 | B28: R3 | C28: 73.2K | D28: mouser | E28: =LEFT(B28,1) -> R | F28: ERA-8AEB7322V | H28: Resistor_SMD:R_1206_3216Metric_Pad1.30x1.75mm_HandSolder | J28: x | K28: =VLOOKUP(F28,Stock!C:G,4,FALSE) -> 0.221 | L28: =IF(ISBLANK(J28),0,A28*K28) -> 0.221
A29: 1 | B29: R6 | C29: 820R | D29: mouser | E29: =LEFT(B29,1) -> R | F29: RT1206FRE07820RL | H29: Resistor_SMD:R_1206_3216Metric_Pad1.30x1.75mm_HandSolder | J29: x | K29: =VLOOKUP(F29,Stock!C:G,4,FALSE) -> 0.034 | L29: =IF(ISBLANK(J29),0,A29*K29) -> 0.034
A30: 1 | B30: SW2 | C30: Blue Button | D30: mouser | E30: =LEFT(B30,1) -> S | F30: TS11-674-43-BK-160-RA-D | G30: https://www.cuidevices.com/product/resource/ts11.pdf | H30: SamacSys_Parts:TS1167443BK160RAD | K30: =VLOOKUP(F30,Stock!C:G,4,FALSE) -> 0.136 | L30: =IF(ISBLANK(J30),0,A30*K30) -> 0
A31: 1 | B31: SW3 | C31: Gold Button | D31: mouser | E31: =LEFT(B31,1) -> S | F31: TS11-674-43-BK-160-RA-D | G31: https://www.cuidevices.com/product/resource/ts11.pdf | H31: SamacSys_Parts:TS1167443BK160RAD | K31: =VLOOKUP(F31,Stock!C:G,4,FALSE) -> 0.136 | L31: =IF(ISBLANK(J31),0,A31*K31) -> 0
A32: 1 | B32: SW1 | C32: Pico Reset | D32: mouser | E32: =LEFT(B32,1) -> S | F32: TS11-674-43-BK-160-RA-D | G32: https://www.cuidevices.com/product/resource/ts11.pdf | H32: SamacSys_Parts:TS1167443BK160RAD | J32: x | K32: =VLOOKUP(F32,Stock!C:G,4,FALSE) -> 0.136 | L32: =IF(ISBLANK(J32),0,A32*K32) -> 0.136
A33: 1 | B33: Y1 | C33: ABM-40MHZ | D33: mouser | E33: =LEFT(B33,1) -> Y | F33: ABM3-40.000MHZ-B2-T | G33: https://abracon.com/Resonators/abm3.pdf | H33: SamacSys_Parts:ABM3 | J33: x | K33: =VLOOKUP(F33,Stock!C:G,4,FALSE) -> 0.363 | L33: =IF(ISBLANK(J33),0,A33*K33) -> 0.363
A34: 1 | B34: A1 | C34: Pololu_A4988 | E34: =LEFT(B34,1) -> A | G34: https://www.pololu.com/product/2980/pictures | H34: Module:Pololu_Breakout-16_15.2x20.3mm | L34: =IF(ISBLANK(J34),0,A34*K34) -> 0
A35: 1 | B35: J19 | C35: 3.3 volt | E35: =LEFT(B35,1) -> J | G35: ~ | H35: TerminalBlock_TE-Connectivity:TerminalBlock_TE_282834-2_1x02_P2.54mm_Horizontal | L35: =IF(ISBLANK(J35),0,A35*K35) -> 0
A36: 1 | B36: J18 | C36: 5 volt | E36: =LEFT(B36,1) -> J | G36: ~ | H36: TerminalBlock_TE-Connectivity:TerminalBlock_TE_282834-2_1x02_P2.54mm_Horizontal | L36: =IF(ISBLANK(J36),0,A36*K36) -> 0
A37: 3 | B37: JP7,JP8,JP9 | C37: Address | E37: =LEFT(B37,1) -> J | H37: Jumper:SolderJumper-2_P1.3mm_Open_Pad1.0x1.5mm | L37: =IF(ISBLANK(J37),0,A37*K37) -> 0
A38: 1 | B38: J22 | C38: AGND | E38: =LEFT(B38,1) -> J | G38: ~ | H38: Connector_PinHeader_2.54mm:PinHeader_1x03_P2.54mm_Vertical | L38: =IF(ISBLANK(J38),0,A38*K38) -> 0
A39: 1 | B39: J20 | C39: Barrel Jack | E39: =LEFT(B39,1) -> J | G39: ~ | H39: Connector_BarrelJack:BarrelJack_Horizontal | J39: x | K39: 0.5 | L39: =IF(ISBLANK(J39),0,A39*K39) -> 0.5
A40: 1 | B40: J7 | C40: Conn_01x04 | E40: =LEFT(B40,1) -> J | G40: ~ | H40: Connector_PinSocket_2.54mm:PinSocket_1x04_P2.54mm_Vertical | L40: =IF(ISBLANK(J40),0,A40*K40) -> 0
...

Sheet LCC-Pico-Stepper_v2_4B
A1: Qty | B1: Reference | C1: Value | D1: source | E1: code | F1: part | G1: Datasheet | H1: Footprint | I1: DNP
A2: 2 | B2: C1,C3 | C2: 0.1uF | D2: mouser | E2: =LEFT(B2,1) -> C | F2: C1206C104K3RAC7411 | G2: ~ | H2: Capacitor_SMD:C_1206_3216Metric_Pad1.33x1.80mm_HandSolder
A3: 2 | B3: C6,C19 | C3: 100nF | D3: mouser | E3: =LEFT(B3,1) -> C | F3: C1206C104K3RAC7411 | G3: ~ | H3: Capacitor_SMD:C_1206_3216Metric_Pad1.33x1.80mm_HandSolder
A4: 1 | B4: C7 | C4: 1uF | D4: mouser | E4: =LEFT(B4,1) -> C | F4: CL31B105KAHNFNE | G4: ~ | H4: Capacitor_SMD:C_1206_3216Metric_Pad1.33x1.80mm_HandSolder
A5: 2 | B5: C13,C14 | C5: 22pF | D5: mouser | E5: =LEFT(B5,1) -> C | F5: C1206C220J3HACTU | G5: ~ | H5: Capacitor_SMD:C_1206_3216Metric_Pad1.33x1.80mm_HandSolder
A6: 7 | B6: C4,C5,C8,C9,C10,C11,C12 | C6: 22uF | D6: mouser | E6: =LEFT(B6,1) -> C | F6: CL31A226MOCLNNC | G6: ~ | H6: Capacitor_SMD:C_1206_3216Metric_Pad1.33x1.80mm_HandSolder
A7: 2 | B7: C15,C16 | C7: 4.7uF | D7: mouser | E7: =LEFT(B7,1) -> C | F7: CL31B475KOHNFNE | G7: ~ | H7: Capacitor_SMD:C_1206_3216Metric_Pad1.33x1.80mm_HandSolder
A8: 1 | B8: C2 | C8: 470uF | D8: mouser | E8: =LEFT(B8,1) -> C | F8: EEU-FR1V471L | G8: ~ | H8: Capacitor_THT:CP_Radial_D8.0mm_P3.50mm
A9: 4 | B9: D4,D5,D7,D8 | C9: LED | D9: mouser | E9: =LEFT(B9,1) -> D | F9: LTST-C230GKT | G9: ~ | H9: LED_SMD:LED_1206_3216Metric_Pad1.42x1.75mm_HandSolder
A10: 4 | B10: D2,D3,D9,D10 | C10: M7 | D10: mouser | E10: =LEFT(B10,1) -> D | F10: M7 | G10: ~ | H10: SamacSys_Parts:DIOM5327X240N
A11: 2 | B11: D6,D11 | C11: PwrG | D11: mouser | E11: =LEFT(B11,1) -> D | F11: LTST-C230GKT | G11: ~ | H11: LED_SMD:LED_1206_3216Metric_Pad1.42x1.75mm_HandSolder
A12: 2 | B12: F1,F2 | C12: 0ZCG0035AF2C | D12: mouser | E12: =LEFT(B12,1) -> F | F12: 0ZCG0035AF2C | G12: https://www.mouser.com/datasheet/2/643/0ZCG_Nov2016-1132141.pdf | H12: SamacSys_Parts:FUSC4632X70N
A13: 1 | B13: IC5 | C13: MB85RCxxxV | D13: mouser | E13: =LEFT(B13,1) -> I | F13: BR24G512F-3AGTE2 | G13: FRAM or EEPROM chip | H13: SamacSys_Parts:SOIC127P600X175-8N
... A19: 1 | B19: Q1 | C19: DMG2305UX-7 | D19: mouser | E19: =LEFT(B19,1) -> Q | F19: DMG2305UX-7 | G19: https://www.diodes.com//assets/Datasheets/DMG2305UX.pdf | H19: SamacSys_Parts:SOT96P240X115-3N
A20: 5 | B20: R8,R9,R13,R14,R16 | C20: 10K | D20: mouser | E20: =LEFT(B20,1) -> R | F20: RT1206FRD0710KL | H20: Resistor_SMD:R_1206_3216Metric_Pad1.30x1.75mm_HandSolder
A21: 1 | B21: R1 | C21: 124K | D21: mouser | E21: =LEFT(B21,1) -> R | F21: ERA-8AEB1243V | H21: Resistor_SMD:R_1206_3216Metric_Pad1.30x1.75mm_HandSolder
A22: 2 | B22: R2,R4 | C22: 22.1K | D22: mouser | E22: =LEFT(B22,1) -> R | F22: ERA-8AEB2212V | H22: Resistor_SMD:R_1206_3216Metric_Pad1.30x1.75mm_HandSolder
A23: 1 | B23: R11 | C23: 2K | D23: mouser | E23: =LEFT(B23,1) -> R | F23: RT1206FRE072KL | H23: Resistor_SMD:R_1206_3216Metric_Pad1.30x1.75mm_HandSolder
A24: 3 | B24: R5,R10,R12 | C24: 3K | D24: mouser | E24: =LEFT(B24,1) -> R | F24: RT1206FRE073KL | H24: Resistor_SMD:R_1206_3216Metric_Pad1.30x1.75mm_HandSolder
A25: 1 | B25: R7 | C25: 560R | D25: mouser | E25: =LEFT(B25,1) -> R | F25: RT1206FRE07560RL | H25: Resistor_SMD:R_1206_3216Metric_Pad1.30x1.75mm_HandSolder
A26: 1 | B26: R15 | C26: 6k8 | D26: mouser | E26: =LEFT(B26,1) -> R | F26: RT1206DRD076K8L | H26: Resistor_SMD:R_1206_3216Metric_Pad1.30x1.75mm_HandSolder
A27: 1 | B27: R3 | C27: 73.2K | D27: mouser | E27: =LEFT(B27,1) -> R | F27: ERA-8AEB7322V | H27: Resistor_SMD:R_1206_3216Metric_Pad1.30x1.75mm_HandSolder
A28: 1 | B28: R6 | C28: 820R | D28: mouser | E28: =LEFT(B28,1) -> R | F28: RT1206FRE07820RL | H28: Resistor_SMD:R_1206_3216Metric_Pad1.30x1.75mm_HandSolder
A29: 1 | B29: SW2 | C29: Blue Button | D29: mouser | E29: =LEFT(B29,1) -> S | F29: TS11-674-43-BK-160-RA-D | G29: https://www.cuidevices.com/product/resource/ts11.pdf | H29: SamacSys_Parts:TS1167443BK160RAD
A30: 1 | B30: SW3 | C30: Gold Button | D30: mouser | E30: =LEFT(B30,1) -> S | F30: TS11-674-43-BK-160-RA-D | G30: https://www.cuidevices.com/product/resource/ts11.pdf | H30: SamacSys_Parts:TS1167443BK160RAD
A31: 1 | B31: SW1 | C31: Pico Reset | D31: mouser | E31: =LEFT(B31,1) -> S | F31: TS11-674-43-BK-160-RA-D | G31: https://www.cuidevices.com/product/resource/ts11.pdf | H31: SamacSys_Parts:TS1167443BK160RAD
A32: 1 | B32: Y1 | C32: ABM-40MHZ | D32: mouser | E32: =LEFT(B32,1) -> Y | F32: ABM3-40.000MHZ-B2-T | G32: https://abracon.com/Resonators/abm3.pdf | H32: SamacSys_Parts:ABM3
A33: 1 | B33: A1 | C33: Pololu_A4988 | E33: =LEFT(B33,1) -> A | G33: https://www.pololu.com/product/2980/pictures | H33: Module:Pololu_Breakout-16_15.2x20.3mm
A34: 1 | B34: J19 | C34: 3.3 volt | E34: =LEFT(B34,1) -> J | G34: ~ | H34: TerminalBlock_TE-Connectivity:TerminalBlock_TE_282834-2_1x02_P2.54mm_Horizontal
A35: 1 | B35: J18 | C35: 5 volt | E35: =LEFT(B35,1) -> J | G35: ~ | H35: TerminalBlock_TE-Connectivity:TerminalBlock_TE_282834-2_1x02_P2.54mm_Horizontal
A36: 3 | B36: JP7,JP8,JP9 | C36: Address | E36: =LEFT(B36,1) -> J | H36: Jumper:SolderJumper-2_P1.3mm_Open_Pad1.0x1.5mm
A37: 1 | B37: J22 | C37: AGND | E37: =LEFT(B37,1) -> J | G37: ~ | H37: Connector_PinHeader_2.54mm:PinHeader_1x03_P2.54mm_Vertical
A38: 1 | B38: J20 | C38: Barrel Jack | E38: =LEFT(B38,1) -> J | G38: ~ | H38: Connector_BarrelJack:BarrelJack_Horizontal
A39: 1 | B39: J7 | C39: Conn_01x04 | E39: =LEFT(B39,1) -> J | G39: ~ | H39: Connector_PinSocket_2.54mm:PinSocket_1x04_P2.54mm_Vertical
A40: 2 | B40: J14,J17 | C40: Conn_01x20 | E40: =LEFT(B40,1) -> J | G40: ~ | H40: Connector_PinHeader_2.54mm:PinHeader_1x20_P2.54mm_Vertical
A41: 2 | B41: J10,J11 | C41: Conn_02x04_Odd_Even | E41: =LEFT(B41,1) -> J | G41: ~ | H41: Connector_PinHeader_2.54mm:PinHeader_2x04_P2.54mm_Vertical
A42: 1 | B42: J4 | C42: Conn_02x05_Odd_Even | E42: =LEFT(B42,1) -> J | G42: ~ | H42: Connector_PinHeader_2.54mm:PinHeader_2x05_P2.54mm_Vertical
A43: 1 | B43: J8 | C43: Conn_02x20_Odd_Even | E43: =LEFT(B43,1) -> J | G43: ~ | H43: Connector_IDC:IDC-Header_2x20_P2.54mm_Vertical
A44: 1 | B44: J23 | C44: Display Power Sel | E44: =LEFT(B44,1) -> J | G44: ~ | H44: Jumper:SolderJumper-3_P1.3mm_Open_RoundedPad1.0x1.5mm
A45: 1 | B45: J16 | C45: FRAM Power Sel | E45: =LEFT(B45,1) -> J | G45: ~ | H45: Jumper:SolderJumper-3_P1.3mm_Open_RoundedPad1.0x1.5mm
...

Sheet LCC-Pico-Stepper_v2_4C
A1: Qty | B1: Reference | C1: Value | D1: source | E1: code | F1: part | G1: Datasheet | H1: Footprint | I1: DNP
A2: 2 | B2: C1,C3 | C2: 0.1uF | D2: mouser | E2: =LEFT(B2,1) -> C | F2: C1206C104K3RAC7411 | G2: ~ | H2: Capacitor_SMD:C_1206_3216Metric_Pad1.33x1.80mm_HandSolder
A3: 2 | B3: C6,C19 | C3: 100nF | D3: mouser | E3: =LEFT(B3,1) -> C | F3: C1206C104K3RAC7411 | G3: ~ | H3: Capacitor_SMD:C_1206_3216Metric_Pad1.33x1.80mm_HandSolder
A4: 1 | B4: C7 | C4: 1uF | D4: mouser | E4: =LEFT(B4,1) -> C | F4: CL31B105KAHNFNE | G4: ~ | H4: Capacitor_SMD:C_1206_3216Metric_Pad1.33x1.80mm_HandSolder
A5: 7 | B5: C4,C5,C8,C9,C10,C11,C12 | C5: 22uF | D5: mouser | E5: =LEFT(B5,1) -> C | F5: CL31A226MOCLNNC | G5: ~ | H5: Capacitor_SMD:C_1206_3216Metric_Pad1.33x1.80mm_HandSolder
A6: 1 | B6: C16 | C6: 4.7uF | D6: mouser | E6: =LEFT(B6,1) -> C | F6: CL31B475KOHNFNE | G6: ~ | H6: Capacitor_SMD:C_1206_3216Metric_Pad1.33x1.80mm_HandSolder
A7: 1 | B7: C2 | C7: 470uF | D7: mouser | E7: =LEFT(B7,1) -> C | F7: EEU-FR1V471L | G7: ~ | H7: Capacitor_THT:CP_Radial_D8.0mm_P3.50mm
A8: 4 | B8: D4,D5,D7,D8 | C8: LED | D8: mouser | E8: =LEFT(B8,1) -> D | F8: LTST-C230GKT | G8: ~ | H8: LED_SMD:LED_1206_3216Metric_Pad1.42x1.75mm_HandSolder
A9: 4 | B9: D2,D3,D9,D10 | C9: M7 | D9: mouser | E9: =LEFT(B9,1) -> D | F9: M7 | G9: ~ | H9: SamacSys_Parts:DIOM5327X240N
A10: 2 | B10: D6,D11 | C10: PwrG | D10: mouser | E10: =LEFT(B10,1) -> D | F10: LTST-C230GKT | G10: ~ | H10: LED_SMD:LED_1206_3216Metric_Pad1.42x1.75mm_HandSolder
A11: 2 | B11: F1,F2 | C11: 0ZCG0035AF2C | D11: mouser | E11: =LEFT(B11,1) -> F | F11: 0ZCG0035AF2C | G11: https://www.mouser.com/datasheet/2/643/0ZCG_Nov2016-1132141.pdf | H11: SamacSys_Parts:FUSC4632X70N
A12: 1 | B12: IC5 | C12: MB85RCxxxV | D12: mouser | E12: =LEFT(B12,1) -> I | F12: BR24G512F-3AGTE2 | G12: FRAM or EEPROM chip | H12: SamacSys_Parts:SOIC127P600X175-8N
A13: 1 | B13: IC3 | C13: TJA1042T_3_1J | D13: mouser | E13: =LEFT(B13,1) -> I | F13: MCP2562FDT-E/SN | H13: SamacSys_Parts:SOIC127P600X175-8N
A14: 1 | B14: IC1 | C14: TPS54294PWPR | D14: mouser | E14: =LEFT(B14,1) -> I | F14: TPS54294PWPR | G14: http://www.ti.com/lit/gpn/tps54294 | H14: SamacSys_Parts:SOP65P640X120-17N
A15: 1 | B15: L1 | C15: SRP3212A-2R2M | D15: mouser | E15: =LEFT(B15,1) -> L | F15: SRP3212A-2R2M | G15: https://www.bourns.com/docs/product-datasheets/srp3212.pdf | H15: SamacSys_Parts:INDC3225X120N
A16: 1 | B16: L2 | C16: SRP3212A-3R3M | D16: mouser | E16: =LEFT(B16,1) -> L | F16: SRP3212A-3R3M | G16: https://www.bourns.com/docs/product-datasheets/srp3212.pdf | H16: SamacSys_Parts:INDC3225X120N
A17: 1 | B17: Q1 | C17: DMG2305UX-7 | D17: mouser | E17: =LEFT(B17,1) -> Q | F17: DMG2305UX-7 | G17: https://www.diodes.com//assets/Datasheets/DMG2305UX.pdf | H17: SamacSys_Parts:SOT96P240X115-3N
A18: 5 | B18: R8,R9,R13,R14,R16 | C18: 10K | D18: mouser | E18: =LEFT(B18,1) -> R | F18: RT1206FRD0710KL | H18: Resistor_SMD:R_1206_3216Metric_Pad1.30x1.75mm_HandSolder
A19: 1 | B19: R1 | C19: 124K | D19: mouser | E19: =LEFT(B19,1) -> R | F19: ERA-8AEB1243V | H19: Resistor_SMD:R_1206_3216Metric_Pad1.30x1.75mm_HandSolder
A20: 2 | B20: R2,R4 | C20: 22.1K | D20: mouser | E20: =LEFT(B20,1) -> R | F20: ERA-8AEB2212V | H20: Resistor_SMD:R_1206_3216Metric_Pad1.30x1.75mm_HandSolder
A21: 1 | B21: R11 | C21: 2K | D21: mouser | E21: =LEFT(B21,1) -> R | F21: RT1206FRE072KL | H21: Resistor_SMD:R_1206_3216Metric_Pad1.30x1.75mm_HandSolder
A22: 3 | B22: R5,R10,R12 | C22: 3K | D22: mouser | E22: =LEFT(B22,1) -> R | F22: RT1206FRE073KL | H22: Resistor_SMD:R_1206_3216Metric_Pad1.30x1.75mm_HandSolder
A23: 1 | B23: R7 | C23: 560R | D23: mouser | E23: =LEFT(B23,1) -> R | F23: RT1206FRE07560RL | H23: Resistor_SMD:R_1206_3216Metric_Pad1.30x1.75mm_HandSolder
A24: 1 | B24: R15 | C24: 6k8 | D24: mouser | E24: =LEFT(B24,1) -> R | F24: RT1206DRD076K8L | H24: Resistor_SMD:R_1206_3216Metric_Pad1.30x1.75mm_HandSolder
A25: 1 | B25: R3 | C25: 73.2K | D25: mouser | E25: =LEFT(B25,1) -> R | F25: ERA-8AEB7322V | H25: Resistor_SMD:R_1206_3216Metric_Pad1.30x1.75mm_HandSolder
A26: 1 | B26: R6 | C26: 820R | D26: mouser | E26: =LEFT(B26,1) -> R | F26: RT1206FRE07820RL | H26: Resistor_SMD:R_1206_3216Metric_Pad1.30x1.75mm_HandSolder
A27: 1 | B27: SW2 | C27: Blue Button | D27: mouser | E27: =LEFT(B27,1) -> S | F27: TS11-674-43-BK-160-RA-D | G27: https://www.cuidevices.com/product/resource/ts11.pdf | H27: SamacSys_Parts:TS1167443BK160RAD
A28: 1 | B28: SW3 | C28: Gold Button | D28: mouser | E28: =LEFT(B28,1) -> S | F28: TS11-674-43-BK-160-RA-D | G28: https://www.cuidevices.com/product/resource/ts11.pdf | H28: SamacSys_Parts:TS1167443BK160RAD
A29: 1 | B29: SW1 | C29: Pico Reset | D29: mouser | E29: =LEFT(B29,1) -> S | F29: TS11-674-43-BK-160-RA-D | G29: https://www.cuidevices.com/product/resource/ts11.pdf | H29: SamacSys_Parts:TS1167443BK160RAD
A30: 1 | B30: A1 | C30: Pololu_A4988 | E30: =LEFT(B30,1) -> A | G30: https://www.pololu.com/product/2980/pictures | H30: Module:Pololu_Breakout-16_15.2x20.3mm
A31: 1 | B31: J19 | C31: 3.3 volt | E31: =LEFT(B31,1) -> J | G31: ~ | H31: TerminalBlock_TE-Connectivity:TerminalBlock_TE_282834-2_1x02_P2.54mm_Horizontal
A32: 1 | B32: J18 | C32: 5 volt | E32: =LEFT(B32,1) -> J | G32: ~ | H32: TerminalBlock_TE-Connectivity:TerminalBlock_TE_282834-2_1x02_P2.54mm_Horizontal
A33: 3 | B33: JP7,JP8,JP9 | C33: Address | E33: =LEFT(B33,1) -> J | H33: Jumper:SolderJumper-2_P1.3mm_Open_Pad1.0x1.5mm
A34: 1 | B34: J22 | C34: AGND | E34: =LEFT(B34,1) -> J | G34: ~ | H34: Connector_PinHeader_2.54mm:PinHeader_1x03_P2.54mm_Vertical
A35: 1 | B35: J20 | C35: Barrel Jack | E35: =LEFT(B35,1) -> J | G35: ~ | H35: Connector_BarrelJack:BarrelJack_Horizontal
A36: 1 | B36: J7 | C36: Conn_01x04 | E36: =LEFT(B36,1) -> J | G36: ~ | H36: Connector_PinSocket_2.54mm:PinSocket_1x04_P2.54mm_Vertical
A37: 2 | B37: J14,J17 | C37: Conn_01x20 | E37: =LEFT(B37,1) -> J | G37: ~ | H37: Connector_PinHeader_2.54mm:PinHeader_1x20_P2.54mm_Vertical
A38: 2 | B38: J10,J11 | C38: Conn_02x04_Odd_Even | E38: =LEFT(B38,1) -> J | G38: ~ | H38: Connector_PinHeader_2.54mm:PinHeader_2x04_P2.54mm_Vertical
A39: 1 | B39: J4 | C39: Conn_02x05_Odd_Even | E39: =LEFT(B39,1) -> J | G39: ~ | H39: Connector_PinHeader_2.54mm:PinHeader_2x05_P2.54mm_Vertical
A40: 1 | B40: J8 | C40: Conn_02x20_Odd_Even | E40: =LEFT(B40,1) -> J | G40: ~ | H40: Connector_IDC:IDC-Header_2x20_P2.54mm_Vertical
...

Sheet Stock
B1: Mouser #: | C1: Mfr. #: | D1: Desc.: | E1: Order Qty. | F1: Ext. (USD) | G1: Price (USD) | H1: Status | I1: Date
B2: 595-TPS54294PWPR | C2: TPS54294PWPR | D2: Switching Voltage Regulators Switching Voltage Regulators 4.5-18Vin,Dual 2A Out,Sync SD Cnvrtr | E2: 20 | F2: 1.66 | G2: 1.66 | H2: 20 Shipped | I2: 45635
B3: 603-RT1206FRD0710KL | C3: RT1206FRD0710KL | D3: Thin Film Resistors - SMD Thin Film Resistors - SMD 10K OHM 1% 25PPM 1/4W | E3: 100 | F3: 0.035 | G3: 0.035 | H3: 100 Shipped | I3: 45635
B4: 603-RT1206FRE073KL | C4: RT1206FRE073KL | D4: Thin Film Resistors - SMD Thin Film Resistors - SMD 3K OHM 1% 50PPM 1/4W | E4: 100 | F4: 0.034 | G4: 0.034 | H4: 100 Shipped | I4: 45635
B5: 638-EAST3215BA3 | C5: EAST3215BA3 | D5: Single Color LEDs Single Color LEDs Top-View PCB | E5: 50 | F5: 0.106 | G5: 0.106 | H5: 50 Shipped | I5: 45635
B6: 859-LTST-S321KRKT | C6: LTST-S321KRKT | D6: Single Color LEDs Single Color LEDs Red 631nm 54mcd Clear | E6: 100 | F6: 0.083 | G6: 0.083 | H6: 100 Shipped | I6: 45635
B7: 859-LTST-C230GKT | C7: LTST-C230GKT | D7: Single Color LEDs Single Color LEDs Green Clear 569nm | E7: 100 | F7: 0.061 | G7: 0.061 | H7: 100 Shipped | I7: 45635
B8: 859-LTST-S110KSKT | C8: LTST-S110KSKT | D8: Single Color LEDs Single Color LEDs Yellow Clear 587nm | E8: 100 | F8: 0.067 | G8: 0.067 | H8: 100 Shipped | I8: 45635
B9: 579-MCP2518FDT-E/SL | C9: MCP2518FDT-E/SL | D9: CAN Interface IC CAN Interface IC Stand-alone Low Power CAN FD Controller w/SPI Interface Grade1 | E9: 10 | F9: 1.96 | G9: 1.96 | H9: 10 Shipped | I9: 45621
B10: 652-SRP3212A-2R2M | C10: SRP3212A-2R2M | D10: Power Inductors - SMD Power Inductors - SMD Ind,3.2x2.5x1mm,2.2uH+/-20%,4A,shd AEC-Q200 | E10: 10 | F10: 0.171 | G10: 0.171 | H10: 10 Shipped | I10: 45621
B11: 652-SRP3212A-3R3M | C11: SRP3212A-3R3M | D11: Power Inductors - SMD Power Inductors - SMD Ind,3.2x2.5x1mm,3.3uH+/-20%,3.1A,shd AEC-Q200 | E11: 10 | F11: 0.172 | G11: 0.172 | H11: 10 Shipped | I11: 45621
B12: 667-ERA-8AEB7322V | C12: ERA-8AEB7322V | D12: Thin Film Resistors - SMD Thin Film Resistors - SMD 1206 73.2Kohm 25ppm 0.1% AEC-Q200 | E12: 10 | F12: 0.221 | G12: 0.221 | H12: 10 Shipped | I12: 45621
B13: 667-ERA-8AEB2212V | C13: ERA-8AEB2212V | D13: Thin Film Resistors - SMD Thin Film Resistors - SMD 1206 22.1Kohm 25ppm 0.1% AEC-Q200 | E13: 20 | F13: 0.278 | G13: 0.278 | H13: 20 Shipped | I13: 45621
... B26: 667-EEU-FR1V471L | C26: EEU-FR1V471L | D26: Aluminum Electrolytic Capacitors - Radial Leaded Aluminum Electrolytic Capacitors - Radial Leaded 35VDC 470uF 8x20mm LS5mm | E26: 10 | F26: 0.3 | G26: 0.3 | H26: 10 Shipped | I26: 45621
B29: Mouser Part Number | C29: Manufacturer Part Number | D29: Description | E29: Quantity | F29: Unit Price | G29: Extended Price
F30: (USD) | G30: (USD)
B32: 187-CL31B475KOHNFNE | C32: CL31B475KOHNFNE | D32: 4.7uF+/-10% 16V X7R | E32: 100 | F32: 0.048 | G32: 4.8
B33: 249-MB85RC256VBCERE1 | C33: MB85RC256VPF-G-BCERE1 | D33: 256kbit FRAM with I2 | E33: 1 | F33: 4.21 | G33: 4.21
B34: 579-MCP251863T-H/SS | C34: MCP251863T-H/SS | D34: CAN FD Controller an | E34: 5 | F34: 2.34 | G34: 11.7
B35: 579-MCP2562FD-E/P | C35: MCP2562FD-E/P | D35: CAN Flexible Data Ra | E35: 4 | F35: 1.38 | G35: 5.52
B36: 579-MCP2562FDT-E/SN | C36: MCP2562FDT-E/SN | D36: CAN Flexible Data Ra | E36: 10 | F36: 1.29 | G36: 12.9
B37: 581-REF1016471M035K | C37: REF1016471M035K | D37: ALUMINUM RADIAL | E37: 10 | F37: 0.294 | G37: 2.94
B38: 603-RT1206DRD076K8L | C38: RT1206DRD076K8L | D38: 6.8 kOhms 250 mW 0.5 | E38: 100 | F38: 0.071 | G38: 7.1
B39: 603-RT1206FRE07560RL | C39: RT1206FRE07560RL | D39: 560 OHM 1% 50PPM 1/4 | E39: 100 | F39: 0.034 | G39: 3.4
B40: 603-RT1206FRE07820RL | C40: RT1206FRE07820RL | D40: 1/4W 820 ohm 1% 50pp | E40: 100 | F40: 0.034 | G40: 3.4
B41: 709-GSM60B15-P1J | C41: GSM60B15-P1J | D41: 60W 15V 4A 2 Pole Me | E41: 1 | F41: 23.96 | G41: 23.96
B42: 709-GSM90B15-P1M | C42: GSM90B15-P1M | D42: 90W 15V 6A Medical A | E42: 1 | F42: 34.79 | G42: 34.79
B43: 755-BR24G512F-3AGTE2 | C43: BR24G512F-3AGTE2 | D43: I2C BUS(2-Wre) 512K | E43: 10 | F43: 0.744 | G43: 7.44
... B45: 815-ABM8-40-10-1-U-T | C45: ABM8-40.000MHZ-10-1-U-T | D45: CRYSTAL 40.0000MHZ 1 | E45: 5 | F45: 0.43 | G45: 2.15
B51: 771-TJA1042T/3/1J | C51: TJA1042T/3/1J | D51: CAN Interface IC CAN Interface IC High-speed CAN transceiver | E51: 10 | F51: 1.23 | G51: 1.23 | H51: 10 Shipped | I51: 45621
B53: 771-PESD1CAN-T/R | C53: PESD1CAN,215 | D53: ESD Protection Diodes / TVS Diodes ESD Protection Diodes / TVS Diodes PESD1CAN/SOT23/TO-236AB | E53: 10 | F53: 0.213 | G53: 0.213 | H53: 10 Shipped | I53: 45621
B54: 595-ISO1050DUBR | C54: ISO1050DUBR | D54: Digital Isolators Digital Isolators Iso 5V CAN Xcvr | E54: 10 | F54: 2.24 | G54: 2.24 | H54: 10 Shipped | I54: 45621
B55: 710-885012208049 | C55: 885012208049 | D55: Multilayer Ceramic Capacitors MLCC - SMD/SMT Multilayer Ceramic Capacitors MLCC - SMD/SMT WCAP-CSGP 3300pF 1206 10% 25V MLCC | E55: 20 | F55: 0.129 | G55: 0.129 | H55: 20 Shipped | I55: 45621
B57: 595-TPS54295PWPR | C57: TPS54295PWPR | D57: Switching Voltage Regulators Switching Voltage Regulators 4.5-18Vin,Dual 2A Out Sync SD Converter | E57: 10 | F57: 1.66 | G57: 1.66 | H57: 10 Shipped | I57: 45621
D62: Aluminum Electrolytic Capacitors - Radial Leaded Aluminum Electrolytic Capacitors - Radial Leaded 35VDC 470uF 10x??mm
